Workbook

Sheet LeiaMe
A1: Treino padrão de cadastro — regras de referência
A3: COMO USAR
A4: 1. Aba Gerador: escolha sexo, nível e objetivos (Sim/Não). O treino padrão aparece por dia, com séries, repetições e descanso, e a checagem de volume semanal mostra 'OK/Abaixo/Acima' por grupo.
A5: 2. Abas Niveis e Objetivos: parâmetros editáveis (azul). Aba Sessoes: templates de dia/slot. Aba Exercicios: lista padrão e ORDEM de preferência. Aba Algoritmo: passo a passo e pseudocódigo.
A7: O QUE CADA VARIÁVEL DECIDE
A8: NÍVEL: frequência semanal, volume, séries por exercício, esforço (RIR), quantos exercícios por sessão e quais exercícios são elegíveis (nível mínimo do exercício ≤ nível).
A9: OBJETIVO: repetições, descanso, cardio semanal, limite de dias (Criar uma Rotina e Saúde & Bem-estar = 3) e teto de nível. Vários objetivos: vale o de menor prioridade; o cardio usa o maior valor.
A10: SEXO: NÃO muda carga, repetições nem descanso. Muda só a ênfase de 2 slots por semana (linhas com Sexo = M, F ou N na aba Sessoes): Masculino = peito/panturrilha; Feminino = ombros (laterais)/glúteos; Não informar = bíceps ou tríceps/abdômen.
A12: PREMISSAS E LIMITAÇÕES
A13: • A diferença de sexo na prescrição de treino é pequena na literatura; a ênfase acima é uma escolha de PRODUTO (preferências típicas), não uma exigência fisiológica. Para um treino idêntico, troque o Sexo dessas linhas para 'Todos' (e apague as alternativas duplicadas).
A14: • Faixas de volume por nível, divisões de treino, ordem de prioridade dos objetivos, teto de nível por objetivo e ordem dos exercícios são regras do projeto (não vêm de uma única fonte). Revise com um profissional de educação física.
A15: • A seleção de exercício usa a ordem da lista: dentro de cada Grupo+Tipo, o primeiro exercício disponível para o nível é o preferido.
... A23: Fundo amarelo + texto azul = entrada do usuário | Texto azul = parâmetro editável | Texto preto = fórmula/texto | Fundo cinza = cálculo auxiliar.

Sheet Gerador
A1: Gerador do treino padrão de cadastro
A2: Preencha as células amarelas (sexo, nível e objetivos). O treino padrão e a checagem de volume semanal recalculam sozinhos. Exemplo pré-preenchido: mulher, Intermediário, objetivo Ganhar Massa Muscular.
I3: CHECAGEM DE VOLUME SEMANAL (direto, por grupo)
A4: DADOS DO USUÁRIO | I4: Grupo muscular | J4: Classe | K4: Exercícios/sem | L4: Séries/sem | M4: Faixa da regra | N4: Status
A5: Sexo | B5: Masculino | I5: Peito | J5: Grande | K5: =COUNTIFS(Sessoes!$D$5:$D$200,I5,Sessoes!$K$5:$K$200,1) -> 5 | L5: =K5*$B$22 -> 20 | M5: =IF(J5="Grande",INDEX(Niveis!$D$5:$D$7,MATCH($B$19,Niveis!$A$5:$A$7,0))&" a "&INDEX(Niveis!$E$5:$E$7,MATCH($B$19,Niveis!$A$5:$A$7,0)),IF(J5="Pequeno",INDEX(Niveis!$F$5:$F$7,MATCH($B$19,Niveis!$A$5:$A$7,0))&" a "&INDEX(Niveis!$G$5:$G$7,MATCH($B$19,Niveis!$A$5:$A$7,0)),"—")) -> 14 a 20 | N5: =IF(J5="Acessório","—",IF(L5<IF(J5="Grande",INDEX(Niveis!$D$5:$D$7,MATCH($B$19,Niveis!$A$5:$A$7,0)),INDEX(Niveis!$F$5:$F$7,MATCH($B$19,Niveis!$A$5:$A$7,0))),"Abaixo",IF(L5>IF(J5="Grande",INDEX(Niveis!$E$5:$E$7,MATCH($B$19,Niveis!$A$5:$A$7,0)),INDEX(Niveis!$G$5:$G$7,MATCH($B$19,Niveis!$A$5:$A$7,0))),"Acima","OK"))) -> OK
A6: Nível físico | B6: Avançado | I6: Costas | J6: Grande | K6: =COUNTIFS(Sessoes!$D$5:$D$200,I6,Sessoes!$K$5:$K$200,1) -> 5 | L6: =K6*$B$22 -> 20 | M6: =IF(J6="Grande",INDEX(Niveis!$D$5:$D$7,MATCH($B$19,Niveis!$A$5:$A$7,0))&" a "&INDEX(Niveis!$E$5:$E$7,MATCH($B$19,Niveis!$A$5:$A$7,0)),IF(J6="Pequeno",INDEX(Niveis!$F$5:$F$7,MATCH($B$19,Niveis!$A$5:$A$7,0))&" a "&INDEX(Niveis!$G$5:$G$7,MATCH($B$19,Niveis!$A$5:$A$7,0)),"—")) -> 14 a 20 | N6: =IF(J6="Acessório","—",IF(L6<IF(J6="Grande",INDEX(Niveis!$D$5:$D$7,MATCH($B$19,Niveis!$A$5:$A$7,0)),INDEX(Niveis!$F$5:$F$7,MATCH($B$19,Niveis!$A$5:$A$7,0))),"Abaixo",IF(L6>IF(J6="Grande",INDEX(Niveis!$E$5:$E$7,MATCH($B$19,Niveis!$A$5:$A$7,0)),INDEX(Niveis!$G$5:$G$7,MATCH($B$19,Niveis!$A$5:$A$7,0))),"Acima","OK"))) -> OK
I7: Ombros | J7: Grande | K7: =COUNTIFS(Sessoes!$D$5:$D$200,I7,Sessoes!$K$5:$K$200,1) -> 4 | L7: =K7*$B$22 -> 16 | M7: =IF(J7="Grande",INDEX(Niveis!$D$5:$D$7,MATCH($B$19,Niveis!$A$5:$A$7,0))&" a "&INDEX(Niveis!$E$5:$E$7,MATCH($B$19,Niveis!$A$5:$A$7,0)),IF(J7="Pequeno",INDEX(Niveis!$F$5:$F$7,MATCH($B$19,Niveis!$A$5:$A$7,0))&" a "&INDEX(Niveis!$G$5:$G$7,MATCH($B$19,Niveis!$A$5:$A$7,0)),"—")) -> 14 a 20 | N7: =IF(J7="Acessório","—",IF(L7<IF(J7="Grande",INDEX(Niveis!$D$5:$D$7,MATCH($B$19,Niveis!$A$5:$A$7,0)),INDEX(Niveis!$F$5:$F$7,MATCH($B$19,Niveis!$A$5:$A$7,0))),"Abaixo",IF(L7>IF(J7="Grande",INDEX(Niveis!$E$5:$E$7,MATCH($B$19,Niveis!$A$5:$A$7,0)),INDEX(Niveis!$G$5:$G$7,MATCH($B$19,Niveis!$A$5:$A$7,0))),"Acima","OK"))) -> OK
A8: Objetivos (Sim/Não) | B8: Selecionado? | C8: Prioridade (aux.) | D8: Cardio min/sem (aux.) | I8: Bíceps | J8: Pequeno | K8: =COUNTIFS(Sessoes!$D$5:$D$200,I8,Sessoes!$K$5:$K$200,1) -> 3 | L8: =K8*$B$22 -> 12 | M8: =IF(J8="Grande",INDEX(Niveis!$D$5:$D$7,MATCH($B$19,Niveis!$A$5:$A$7,0))&" a "&INDEX(Niveis!$E$5:$E$7,MATCH($B$19,Niveis!$A$5:$A$7,0)),IF(J8="Pequeno",INDEX(Niveis!$F$5:$F$7,MATCH($B$19,Niveis!$A$5:$A$7,0))&" a "&INDEX(Niveis!$G$5:$G$7,MATCH($B$19,Niveis!$A$5:$A$7,0)),"—")) -> 6 a 14 | N8: =IF(J8="Acessório","—",IF(L8<IF(J8="Grande",INDEX(Niveis!$D$5:$D$7,MATCH($B$19,Niveis!$A$5:$A$7,0)),INDEX(Niveis!$F$5:$F$7,MATCH($B$19,Niveis!$A$5:$A$7,0))),"Abaixo",IF(L8>IF(J8="Grande",INDEX(Niveis!$E$5:$E$7,MATCH($B$19,Niveis!$A$5:$A$7,0)),INDEX(Niveis!$G$5:$G$7,MATCH($B$19,Niveis!$A$5:$A$7,0))),"Acima","OK"))) -> OK
A9: =Objetivos!$A5 -> Perder Peso | B9: Não | C9: =IF(B9="Sim",Objetivos!$B5,99) -> 99 | D9: =IF(B9="Sim",Objetivos!$H5,0) -> 0 | I9: Tríceps | J9: Pequeno | K9: =COUNTIFS(Sessoes!$D$5:$D$200,I9,Sessoes!$K$5:$K$200,1) -> 3 | L9: =K9*$B$22 -> 12 | M9: =IF(J9="Grande",INDEX(Niveis!$D$5:$D$7,MATCH($B$19,Niveis!$A$5:$A$7,0))&" a "&INDEX(Niveis!$E$5:$E$7,MATCH($B$19,Niveis!$A$5:$A$7,0)),IF(J9="Pequeno",INDEX(Niveis!$F$5:$F$7,MATCH($B$19,Niveis!$A$5:$A$7,0))&" a "&INDEX(Niveis!$G$5:$G$7,MATCH($B$19,Niveis!$A$5:$A$7,0)),"—")) -> 6 a 14 | N9: =IF(J9="Acessório","—",IF(L9<IF(J9="Grande",INDEX(Niveis!$D$5:$D$7,MATCH($B$19,Niveis!$A$5:$A$7,0)),INDEX(Niveis!$F$5:$F$7,MATCH($B$19,Niveis!$A$5:$A$7,0))),"Abaixo",IF(L9>IF(J9="Grande",INDEX(Niveis!$E$5:$E$7,MATCH($B$19,Niveis!$A$5:$A$7,0)),INDEX(Niveis!$G$5:$G$7,MATCH($B$19,Niveis!$A$5:$A$7,0))),"Acima","OK"))) -> OK
A10: =Objetivos!$A6 -> Ganhar Massa Muscular | B10: Sim | C10: =IF(B10="Sim",Objetivos!$B6,99) -> 1 | D10: =IF(B10="Sim",Objetivos!$H6,0) -> 60 | I10: Quadríceps | J10: Grande | K10: =COUNTIFS(Sessoes!$D$5:$D$200,I10,Sessoes!$K$5:$K$200,1) -> 4 | L10: =K10*$B$22 -> 16 | M10: =IF(J10="Grande",INDEX(Niveis!$D$5:$D$7,MATCH($B$19,Niveis!$A$5:$A$7,0))&" a "&INDEX(Niveis!$E$5:$E$7,MATCH($B$19,Niveis!$A$5:$A$7,0)),IF(J10="Pequeno",INDEX(Niveis!$F$5:$F$7,MATCH($B$19,Niveis!$A$5:$A$7,0))&" a "&INDEX(Niveis!$G$5:$G$7,MATCH($B$19,Niveis!$A$5:$A$7,0)),"—")) -> 14 a 20 | N10: =IF(J10="Acessório","—",IF(L10<IF(J10="Grande",INDEX(Niveis!$D$5:$D$7,MATCH($B$19,Niveis!$A$5:$A$7,0)),INDEX(Niveis!$F$5:$F$7,MATCH($B$19,Niveis!$A$5:$A$7,0))),"Abaixo",IF(L10>IF(J10="Grande",INDEX(Niveis!$E$5:$E$7,MATCH($B$19,Niveis!$A$5:$A$7,0)),INDEX(Niveis!$G$5:$G$7,MATCH($B$19,Niveis!$A$5:$A$7,0))),"Acima","OK"))) -> OK
A11: =Objetivos!$A7 -> Melhorar Condicionamento | B11: Não | C11: =IF(B11="Sim",Objetivos!$B7,99) -> 99 | D11: =IF(B11="Sim",Objetivos!$H7,0) -> 0 | I11: Posterior de coxa | J11: Grande | K11: =COUNTIFS(Sessoes!$D$5:$D$200,I11,Sessoes!$K$5:$K$200,1) -> 4 | L11: =K11*$B$22 -> 16 | M11: =IF(J11="Grande",INDEX(Niveis!$D$5:$D$7,MATCH($B$19,Niveis!$A$5:$A$7,0))&" a "&INDEX(Niveis!$E$5:$E$7,MATCH($B$19,Niveis!$A$5:$A$7,0)),IF(J11="Pequeno",INDEX(Niveis!$F$5:$F$7,MATCH($B$19,Niveis!$A$5:$A$7,0))&" a "&INDEX(Niveis!$G$5:$G$7,MATCH($B$19,Niveis!$A$5:$A$7,0)),"—")) -> 14 a 20 | N11: =IF(J11="Acessório","—",IF(L11<IF(J11="Grande",INDEX(Niveis!$D$5:$D$7,MATCH($B$19,Niveis!$A$5:$A$7,0)),INDEX(Niveis!$F$5:$F$7,MATCH($B$19,Niveis!$A$5:$A$7,0))),"Abaixo",IF(L11>IF(J11="Grande",INDEX(Niveis!$E$5:$E$7,MATCH($B$19,Niveis!$A$5:$A$7,0)),INDEX(Niveis!$G$5:$G$7,MATCH($B$19,Niveis!$A$5:$A$7,0))),"Acima","OK"))) -> OK
A12: =Objetivos!$A8 -> Aumentar Resistência | B12: Não | C12: =IF(B12="Sim",Objetivos!$B8,99) -> 99 | D12: =IF(B12="Sim",Objetivos!$H8,0) -> 0 | I12: Glúteos | J12: Grande | K12: =COUNTIFS(Sessoes!$D$5:$D$200,I12,Sessoes!$K$5:$K$200,1) -> 4 | L12: =K12*$B$22 -> 16 | M12: =IF(J12="Grande",INDEX(Niveis!$D$5:$D$7,MATCH($B$19,Niveis!$A$5:$A$7,0))&" a "&INDEX(Niveis!$E$5:$E$7,MATCH($B$19,Niveis!$A$5:$A$7,0)),IF(J12="Pequeno",INDEX(Niveis!$F$5:$F$7,MATCH($B$19,Niveis!$A$5:$A$7,0))&" a "&INDEX(Niveis!$G$5:$G$7,MATCH($B$19,Niveis!$A$5:$A$7,0)),"—")) -> 14 a 20 | N12: =IF(J12="Acessório","—",IF(L12<IF(J12="Grande",INDEX(Niveis!$D$5:$D$7,MATCH($B$19,Niveis!$A$5:$A$7,0)),INDEX(Niveis!$F$5:$F$7,MATCH($B$19,Niveis!$A$5:$A$7,0))),"Abaixo",IF(L12>IF(J12="Grande",INDEX(Niveis!$E$5:$E$7,MATCH($B$19,Niveis!$A$5:$A$7,0)),INDEX(Niveis!$G$5:$G$7,MATCH($B$19,Niveis!$A$5:$A$7,0))),"Acima","OK"))) -> OK
A13: =Objetivos!$A9 -> Criar uma Rotina | B13: Não | C13: =IF(B13="Sim",Objetivos!$B9,99) -> 99 | D13: =IF(B13="Sim",Objetivos!$H9,0) -> 0 | I13: Panturrilha | J13: Pequeno | K13: =COUNTIFS(Sessoes!$D$5:$D$200,I13,Sessoes!$K$5:$K$200,1) -> 3 | L13: =K13*$B$22 -> 12 | M13: =IF(J13="Grande",INDEX(Niveis!$D$5:$D$7,MATCH($B$19,Niveis!$A$5:$A$7,0))&" a "&INDEX(Niveis!$E$5:$E$7,MATCH($B$19,Niveis!$A$5:$A$7,0)),IF(J13="Pequeno",INDEX(Niveis!$F$5:$F$7,MATCH($B$19,Niveis!$A$5:$A$7,0))&" a "&INDEX(Niveis!$G$5:$G$7,MATCH($B$19,Niveis!$A$5:$A$7,0)),"—")) -> 6 a 14 | N13: =IF(J13="Acessório","—",IF(L13<IF(J13="Grande",INDEX(Niveis!$D$5:$D$7,MATCH($B$19,Niveis!$A$5:$A$7,0)),INDEX(Niveis!$F$5:$F$7,MATCH($B$19,Niveis!$A$5:$A$7,0))),"Abaixo",IF(L13>IF(J13="Grande",INDEX(Niveis!$E$5:$E$7,MATCH($B$19,Niveis!$A$5:$A$7,0)),INDEX(Niveis!$G$5:$G$7,MATCH($B$19,Niveis!$A$5:$A$7,0))),"Acima","OK"))) -> OK
A14: =Objetivos!$A10 -> Saúde & Bem-estar | B14: Não | C14: =IF(B14="Sim",Objetivos!$B10,99) -> 99 | D14: =IF(B14="Sim",Objetivos!$H10,0) -> 0 | I14: Abdômen | J14: Pequeno | K14: =COUNTIFS(Sessoes!$D$5:$D$200,I14,Sessoes!$K$5:$K$200,1) -> 2 | L14: =K14*$B$22 -> 8 | M14: =IF(J14="Grande",INDEX(Niveis!$D$5:$D$7,MATCH($B$19,Niveis!$A$5:$A$7,0))&" a "&INDEX(Niveis!$E$5:$E$7,MATCH($B$19,Niveis!$A$5:$A$7,0)),IF(J14="Pequeno",INDEX(Niveis!$F$5:$F$7,MATCH($B$19,Niveis!$A$5:$A$7,0))&" a "&INDEX(Niveis!$G$5:$G$7,MATCH($B$19,Niveis!$A$5:$A$7,0)),"—")) -> 6 a 14 | N14: =IF(J14="Acessório","—",IF(L14<IF(J14="Grande",INDEX(Niveis!$D$5:$D$7,MATCH($B$19,Niveis!$A$5:$A$7,0)),INDEX(Niveis!$F$5:$F$7,MATCH($B$19,Niveis!$A$5:$A$7,0))),"Abaixo",IF(L14>IF(J14="Grande",INDEX(Niveis!$E$5:$E$7,MATCH($B$19,Niveis!$A$5:$A$7,0)),INDEX(Niveis!$G$5:$G$7,MATCH($B$19,Niveis!$A$5:$A$7,0))),"Acima","OK"))) -> OK
I15: Lombar | J15: Acessório | K15: =COUNTIFS(Sessoes!$D$5:$D$200,I15,Sessoes!$K$5:$K$200,1) -> 1 | L15: =K15*$B$22 -> 4 | M15: =IF(J15="Grande",INDEX(Niveis!$D$5:$D$7,MATCH($B$19,Niveis!$A$5:$A$7,0))&" a "&INDEX(Niveis!$E$5:$E$7,MATCH($B$19,Niveis!$A$5:$A$7,0)),IF(J15="Pequeno",INDEX(Niveis!$F$5:$F$7,MATCH($B$19,Niveis!$A$5:$A$7,0))&" a "&INDEX(Niveis!$G$5:$G$7,MATCH($B$19,Niveis!$A$5:$A$7,0)),"—")) -> — | N15: =IF(J15="Acessório","—",IF(L15<IF(J15="Grande",INDEX(Niveis!$D$5:$D$7,MATCH($B$19,Niveis!$A$5:$A$7,0)),INDEX(Niveis!$F$5:$F$7,MATCH($B$19,Niveis!$A$5:$A$7,0))),"Abaixo",IF(L15>IF(J15="Grande",INDEX(Niveis!$E$5:$E$7,MATCH($B$19,Niveis!$A$5:$A$7,0)),INDEX(Niveis!$G$5:$G$7,MATCH($B$19,Niveis!$A$5:$A$7,0))),"Acima","OK"))) -> —
A16: PERFIL DE TREINO DEFINIDO | I16: Antebraço | J16: Acessório | K16: =COUNTIFS(Sessoes!$D$5:$D$200,I16,Sessoes!$K$5:$K$200,1) -> 1 | L16: =K16*$B$22 -> 4 | M16: =IF(J16="Grande",INDEX(Niveis!$D$5:$D$7,MATCH($B$19,Niveis!$A$5:$A$7,0))&" a "&INDEX(Niveis!$E$5:$E$7,MATCH($B$19,Niveis!$A$5:$A$7,0)),IF(J16="Pequeno",INDEX(Niveis!$F$5:$F$7,MATCH($B$19,Niveis!$A$5:$A$7,0))&" a "&INDEX(Niveis!$G$5:$G$7,MATCH($B$19,Niveis!$A$5:$A$7,0)),"—")) -> — | N16: =IF(J16="Acessório","—",IF(L16<IF(J16="Grande",INDEX(Niveis!$D$5:$D$7,MATCH($B$19,Niveis!$A$5:$A$7,0)),INDEX(Niveis!$F$5:$F$7,MATCH($B$19,Niveis!$A$5:$A$7,0))),"Abaixo",IF(L16>IF(J16="Grande",INDEX(Niveis!$E$5:$E$7,MATCH($B$19,Niveis!$A$5:$A$7,0)),INDEX(Niveis!$G$5:$G$7,MATCH($B$19,Niveis!$A$5:$A$7,0))),"Acima","OK"))) -> —
A17: Prioridade do objetivo principal (aux.) | B17: =IF(COUNTIF(B9:B14,"Sim")=0,6,MIN(C9:C14)) -> 1
A18: Objetivo principal | B18: =INDEX(Objetivos!$A$5:$A$10,MATCH(B17,Objetivos!$B$5:$B$10,0)) -> Ganhar Massa Muscular
A19: Nível efetivo | B19: =INDEX(Niveis!$A$5:$A$7,MIN(MATCH($B$6,Niveis!$A$5:$A$7,0),MATCH(INDEX(Objetivos!$K$5:$K$10,MATCH($B$18,Objetivos!$A$5:$A$10,0)),Niveis!$A$5:$A$7,0))) -> Avançado
A20: Frequência semanal (dias) | B20: =MIN(INDEX(Niveis!$B$5:$B$7,MATCH($B$19,Niveis!$A$5:$A$7,0)),INDEX(Objetivos!$J$5:$J$10,MATCH($B$18,Objetivos!$A$5:$A$10,0))) -> 5
A21: Código de sexo para os slots (aux.) | B21: =IF(B5="Masculino","M",IF(B5="Feminino","F","N")) -> M
A22: Séries por exercício | B22: =INDEX(Niveis!$H$5:$H$7,MATCH($B$19,Niveis!$A$5:$A$7,0)) -> 4
A23: Repetições por série | B23: =INDEX(Objetivos!$D$5:$D$10,MATCH($B$18,Objetivos!$A$5:$A$10,0))&" a "&INDEX(Objetivos!$E$5:$E$10,MATCH($B$18,Objetivos!$A$5:$A$10,0)) -> 6 a 12
A24: Descanso — compostos (s) | B24: =INDEX(Objetivos!$F$5:$F$10,MATCH($B$18,Objetivos!$A$5:$A$10,0)) -> 120
A25: Descanso — isolados (s) | B25: =INDEX(Objetivos!$G$5:$G$10,MATCH($B$18,Objetivos!$A$5:$A$10,0)) -> 60
A26: Esforço (RIR) | B26: =INDEX(Niveis!$K$5:$K$7,MATCH($B$19,Niveis!$A$5:$A$7,0)) -> 0–2
A27: Duração recomendada da sessão (min) | B27: =INDEX(Niveis!$C$5:$C$7,MATCH($B$19,Niveis!$A$5:$A$7,0)) -> 80
A28: Cardio semanal (min) | B28: =MAX(D9:D14,INDEX(Objetivos!$H$5:$H$10,MATCH($B$18,Objetivos!$A$5:$A$10,0))) -> 60
A29: Tipo de cardio | B29: =INDEX(Objetivos!$I$5:$I$10,MATCH($B$18,Objetivos!$A$5:$A$10,0)) -> Cardio leve (LISS), sem competir com a recuperação
A30: Observação | B30: =IF(COUNTIF(Sessoes!$K$5:$K$200,1)=0,"ATENÇÃO: não há template para esta combinação de frequência e nível (ver aba Sessoes).",IF(B19<>B6,"Nível reduzido de "&B6&" para "&B19&" pelo objetivo principal ("&B18&").","OK")) -> OK
A32: TREINO PADRÃO GERADO
A33: =IF($B$20<1,"","Dia 1 — "&IFERROR(INDEX(Sessoes!$C$5:$C$200,MATCH($B$20&"-1-1",Sessoes!$M$5:$M$200,0)),"")) -> Dia 1 — Empurrar (Push) | F33: =IF($B$20<1,"",COUNTIF(B35:B46,"?*")&" exercícios") -> 7 exercícios
A34: # | B34: Exercício | C34: Grupo | D34: Tipo | E34: Séries | F34: Repetições | G34: Descanso (s)
A35: =IF(B35="","",1) -> 1 | B35: =IF($B$20<1,"",IFERROR(INDEX(Sessoes!$O$5:$O$200,MATCH($B$20&"-1-1",Sessoes!$M$5:$M$200,0)),"")) -> Supino reto com barra | C35: =IF(B35="","",INDEX(Sessoes!$D$5:$D$200,MATCH($B$20&"-1-1",Sessoes!$M$5:$M$200,0))) -> Peito | D35: =IF(B35="","",INDEX(Sessoes!$E$5:$E$200,MATCH($B$20&"-1-1",Sessoes!$M$5:$M$200,0))) -> Composto | E35: =IF(B35="","",$B$22) -> 4 | F35: =IF(B35="","",$B$23) -> 6 a 12 | G35: =IF(B35="","",IF(D35="Composto",$B$24,$B$25)) -> 120
A36: =IF(B36="","",2) -> 2 | B36: =IF($B$20<1,"",IFERROR(INDEX(Sessoes!$O$5:$O$200,MATCH($B$20&"-1-2",Sessoes!$M$5:$M$200,0)),"")) -> Supino inclinado com barra | C36: =IF(B36="","",INDEX(Sessoes!$D$5:$D$200,MATCH($B$20&"-1-2",Sessoes!$M$5:$M$200,0))) -> Peito | D36: =IF(B36="","",INDEX(Sessoes!$E$5:$E$200,MATCH($B$20&"-1-2",Sessoes!$M$5:$M$200,0))) -> Composto | E36: =IF(B36="","",$B$22) -> 4 | F36: =IF(B36="","",$B$23) -> 6 a 12 | G36: =IF(B36="","",IF(D36="Composto",$B$24,$B$25)) -> 120
A37: =IF(B37="","",3) -> 3 | B37: =IF($B$20<1,"",IFERROR(INDEX(Sessoes!$O$5:$O$200,MATCH($B$20&"-1-3",Sessoes!$M$5:$M$200,0)),"")) -> Desenvolvimento militar com barra | C37: =IF(B37="","",INDEX(Sessoes!$D$5:$D$200,MATCH($B$20&"-1-3",Sessoes!$M$5:$M$200,0))) -> Ombros | D37: =IF(B37="","",INDEX(Sessoes!$E$5:$E$200,MATCH($B$20&"-1-3",Sessoes!$M$5:$M$200,0))) -> Composto | E37: =IF(B37="","",$B$22) -> 4 | F37: =IF(B37="","",$B$23) -> 6 a 12 | G37: =IF(B37="","",IF(D37="Composto",$B$24,$B$25)) -> 120
A38: =IF(B38="","",4) -> 4 | B38: =IF($B$20<1,"",IFERROR(INDEX(Sessoes!$O$5:$O$200,MATCH($B$20&"-1-4",Sessoes!$M$5:$M$200,0)),"")) -> Crossover na polia | C38: =IF(B38="","",INDEX(Sessoes!$D$5:$D$200,MATCH($B$20&"-1-4",Sessoes!$M$5:$M$200,0))) -> Peito | D38: =IF(B38="","",INDEX(Sessoes!$E$5:$E$200,MATCH($B$20&"-1-4",Sessoes!$M$5:$M$200,0))) -> Isolado | E38: =IF(B38="","",$B$22) -> 4 | F38: =IF(B38="","",$B$23) -> 6 a 12 | G38: =IF(B38="","",IF(D38="Composto",$B$24,$B$25)) -> 60
A39: =IF(B39="","",5) -> 5 | B39: =IF($B$20<1,"",IFERROR(INDEX(Sessoes!$O$5:$O$200,MATCH($B$20&"-1-5",Sessoes!$M$5:$M$200,0)),"")) -> Elevação lateral com halteres | C39: =IF(B39="","",INDEX(Sessoes!$D$5:$D$200,MATCH($B$20&"-1-5",Sessoes!$M$5:$M$200,0))) -> Ombros | D39: =IF(B39="","",INDEX(Sessoes!$E$5:$E$200,MATCH($B$20&"-1-5",Sessoes!$M$5:$M$200,0))) -> Isolado | E39: =IF(B39="","",$B$22) -> 4 | F39: =IF(B39="","",$B$23) -> 6 a 12 | G39: =IF(B39="","",IF(D39="Composto",$B$24,$B$25)) -> 60
A40: =IF(B40="","",6) -> 6 | B40: =IF($B$20<1,"",IFERROR(INDEX(Sessoes!$O$5:$O$200,MATCH($B$20&"-1-6",Sessoes!$M$5:$M$200,0)),"")) -> Supino fechado | C40: =IF(B40="","",INDEX(Sessoes!$D$5:$D$200,MATCH($B$20&"-1-6",Sessoes!$M$5:$M$200,0))) -> Tríceps | D40: =IF(B40="","",INDEX(Sessoes!$E$5:$E$200,MATCH($B$20&"-1-6",Sessoes!$M$5:$M$200,0))) -> Composto | E40: =IF(B40="","",$B$22) -> 4 | F40: =IF(B40="","",$B$23) -> 6 a 12 | G40: =IF(B40="","",IF(D40="Composto",$B$24,$B$25)) -> 120
A41: =IF(B41="","",7) -> 7 | B41: =IF($B$20<1,"",IFERROR(INDEX(Sessoes!$O$5:$O$200,MATCH($B$20&"-1-7",Sessoes!$M$5:$M$200,0)),"")) -> Tríceps pulley (corda ou barra) | C41: =IF(B41="","",INDEX(Sessoes!$D$5:$D$200,MATCH($B$20&"-1-7",Sessoes!$M$5:$M$200,0))) -> Tríceps | D41: =IF(B41="","",INDEX(Sessoes!$E$5:$E$200,MATCH($B$20&"-1-7",Sessoes!$M$5:$M$200,0))) -> Isolado | E41: =IF(B41="","",$B$22) -> 4 | F41: =IF(B41="","",$B$23) -> 6 a 12 | G41: =IF(B41="","",IF(D41="Composto",$B$24,$B$25)) -> 60
...

Sheet Algoritmo
A1: Algoritmo de geração do treino padrão (referência para implementação)
A3: ENTRADAS
A4: sexo ∈ {Masculino, Feminino, Não informar} | nivel ∈ {Iniciante, Intermediário, Avançado} | objetivos = subconjunto dos 6 objetivos do app (pode ser vazio)
A6: PASSO A PASSO
A7: 1. principal = objetivo marcado com MENOR número de prioridade (aba Objetivos). Se nenhum marcado: 'Saúde & Bem-estar'.
A8: 2. nivelEfetivo = mínimo entre nivel e principal.nivelMaxVolume (ex.: 'Criar uma Rotina' limita a Iniciante).
A9: 3. frequencia = mínimo entre Niveis[nivelEfetivo].frequencia e principal.frequenciaMax.
A10: 4. series = Niveis[nivelEfetivo].seriesPorExercicio; reps = [principal.repsMin, principal.repsMax]; descanso = principal.descansoComposto / principal.descansoIsolado (por tipo do exercício); RIR = Niveis[nivelEfetivo].rir.
A11: 5. codigoSexo = 'M' | 'F' | 'N' (Não informar).
A12: 6. slots = linhas da aba Sessoes onde dias == frequencia E rank(slot.nivelMin) ≤ rank(nivelEfetivo) E slot.sexo ∈ {'Todos', codigoSexo} (mantendo a ordem das linhas).
A13: 7. elegiveis[grupo][tipo] = exercícios da aba Exercicios com rank(nivelMin) ≤ rank(nivelEfetivo), NA ORDEM da lista.
A14: 8. contador[grupo][tipo] = 0. Para cada slot, em ordem: contador[g][t]++ ; se contador[g][t] > len(elegiveis[g][t]) → descarta o slot; senão exercicio = elegiveis[g][t][contador[g][t] − 1].
... A39: slots(dias, dia, nomeSessao, grupo, tipo, nivelMin, sexo, ordem) — aba Sessoes

Sheet Niveis
A1: Parâmetros por nível físico
A2: Texto azul = parâmetro editável. A ordem das linhas (Iniciante < Intermediário < Avançado) é usada como ranking de nível.
A4: Nível | B4: Frequência semanal (dias) | C4: Duração recomendada (min) | D4: Séries/sem grupos grandes (mín) | E4: Séries/sem grupos grandes (máx) | F4: Séries/sem grupos pequenos (mín) | G4: Séries/sem grupos pequenos (máx) | H4: Séries por exercício | I4: Exercícios/sessão (mín) | J4: Exercícios/sessão (máx) | K4: Esforço (RIR) | L4: Progressão de carga
A5: Iniciante | B5: 3 | C5: 50 | D5: 6 | E5: 10 | F5: 3 | G5: 6 | H5: 3 | I5: 5 | J5: 6 | K5: 3–4 (longe da falha) | L5: Dupla progressão: ao atingir o topo da faixa de repetições em todas as séries, subir ~2–5% da carga. Foco em técnica.
A6: Intermediário | B6: 4 | C6: 65 | D6: 9 | E6: 15 | F6: 3 | G6: 9 | H6: 3 | I6: 6 | J6: 8 | K6: 2–3 | L6: Dupla progressão; última série dos compostos próxima da falha (RIR 1–2). Semana de alívio (deload) a cada 6–8 semanas.
A7: Avançado | B7: 5 | C7: 80 | D7: 14 | E7: 20 | F7: 6 | G7: 14 | H7: 4 | I7: 7 | J7: 10 | K7: 0–2 | L7: Periodização (ondulatória ou em blocos) e deload programado a cada 4–8 semanas.
A9: Grupos grandes: Peito, Costas, Ombros, Quadríceps, Posterior de coxa, Glúteos. Pequenos: Bíceps, Tríceps, Panturrilha, Abdômen. Acessórios (Lombar, Antebraço) não têm meta de volume.
A10: Volume semanal: a literatura associa ≥10 séries/semana por grupo a melhor hipertrofia (Schoenfeld et al., 2017); para iniciantes, volumes menores já geram ganhos. As faixas acima são a regra adotada neste projeto.

Sheet Objetivos
A1: Parâmetros por objetivo
A2: Vários objetivos podem ser marcados: o de menor 'Prioridade' vira o PRINCIPAL e define repetições, descanso, limite de frequência e teto de nível. O cardio usa o maior valor entre os marcados.
A4: Objetivo | B4: Prioridade (1 = maior) | C4: Foco | D4: Reps (mín) | E4: Reps (máx) | F4: Descanso compostos (s) | G4: Descanso isolados (s) | H4: Cardio semanal (min) | I4: Tipo de cardio | J4: Frequência máx. (dias) | K4: Nível máx. de volume | L4: Estratégia
A5: Perder Peso | B5: 2 | C5: Gasto energético e preservação de massa magra | D5: 8 | E5: 15 | F5: 60 | G5: 45 | H5: 150 | I5: Aeróbico moderado (caminhada inclinada, bike, elíptico); 1 sessão intervalada opcional | J5: 7 | K5: Avançado | L5: Musculação completa, descansos curtos/moderados, priorizar compostos. Manter carga para preservar massa magra.
A6: Ganhar Massa Muscular | B6: 1 | C6: Hipertrofia | D6: 6 | E6: 12 | F6: 120 | G6: 60 | H6: 60 | I6: Cardio leve (LISS), sem competir com a recuperação | J6: 7 | K6: Avançado | L6: Volume alto por grupo, compostos pesados primeiro, descansos longos nos compostos, progressão constante de carga.
A7: Melhorar Condicionamento | B7: 4 | C7: Capacidade cardiorrespiratória e muscular | D7: 12 | E7: 20 | F7: 45 | G7: 30 | H7: 150 | I7: Misto: 2 sessões moderadas + 1 intervalada (HIIT) | J7: 7 | K7: Avançado | L7: Repetições mais altas, descansos curtos, ritmo contínuo entre exercícios.
A8: Aumentar Resistência | B8: 3 | C8: Resistência muscular | D8: 15 | E8: 25 | F8: 45 | G8: 30 | H8: 120 | I8: Contínuo moderado com aumento progressivo de duração | J8: 7 | K8: Avançado | L8: Repetições altas, cargas moderadas/leves, descansos curtos; progredir em repetições antes da carga.
A9: Criar uma Rotina | B9: 5 | C9: Aderência e formação de hábito | D9: 10 | E9: 15 | F9: 75 | G9: 60 | H9: 60 | I9: Caminhada leve (opcional) | J9: 3 | K9: Iniciante | L9: Poucas sessões, simples e curtas (corpo todo); a meta é não faltar, não a intensidade.
A10: Saúde & Bem-estar | B10: 6 | C10: Saúde geral (OMS: ≥2 dias de força + 150–300 min aeróbico/semana) | D10: 10 | E10: 15 | F10: 75 | G10: 60 | H10: 150 | I10: Aeróbico moderado (caminhada rápida, bike, natação) | J10: 3 | K10: Intermediário | L10: Corpo todo 2–3×/semana, esforço moderado, equilíbrio entre empurrar/puxar e superior/inferior.
A12: Nível máx. de volume: teto aplicado ao nível do usuário (ex.: quem escolhe 'Criar uma Rotina' recebe o plano de Iniciante, mesmo sendo Avançado). Regra do projeto; edite se preferir.

Sheet Sessoes
A1: Templates de sessão (slots) por frequência semanal
A2: Cada linha é um 'slot': um exercício do grupo/tipo indicado. Entra no treino se: Dias = frequência do usuário, Nível mín. ≤ nível efetivo e Sexo = 'Todos' ou igual ao do usuário (M, F ou N = não informar). Colunas H–O são cálculo (não editar).
A4: Dias/semana | B4: Dia | C4: Sessão | D4: Grupo | E4: Tipo | F4: Nível mín. | G4: Sexo | H4: Passa filtro? | I4: Ordem no grupo/tipo | J4: Opções disponíveis | K4: Incluir? | L4: Posição no dia | M4: Chave do slot | N4: Chave do exercício | O4: Exercício escolhido
A5: 3 | B5: 1 | C5: Corpo todo A | D5: Quadríceps | E5: Composto | F5: Iniciante | G5: Todos | H5: =IF(AND(A5=Gerador!$B$20,MATCH(F5,Niveis!$A$5:$A$7,0)<=MATCH(Gerador!$B$19,Niveis!$A$5:$A$7,0),OR(G5="Todos",G5=Gerador!$B$21)),1,0) -> 0 | I5: =IF(H5=1,COUNTIFS($D$5:D5,D5,$E$5:E5,E5,$H$5:H5,1),0) -> 0 | J5: =COUNTIFS(Exercicios!$C$5:$C$75,D5,Exercicios!$F$5:$F$75,E5,Exercicios!$H$5:$H$75,"Sim") -> 8 | K5: =IF(AND(H5=1,I5<=J5),1,0) -> 0 | L5: =IF(K5=1,COUNTIFS($A$5:A5,A5,$B$5:B5,B5,$K$5:K5,1),0) -> 0 | M5: =IF(K5=1,A5&"-"&B5&"-"&L5,"") | N5: =IF(K5=1,D5&"-"&E5&"-"&I5,"") | O5: =IF(K5=1,INDEX(Exercicios!$B$5:$B$75,MATCH(N5,Exercicios!$I$5:$I$75,0)),"")
A6: 3 | B6: 1 | C6: Corpo todo A | D6: Peito | E6: Composto | F6: Iniciante | G6: Todos | H6: =IF(AND(A6=Gerador!$B$20,MATCH(F6,Niveis!$A$5:$A$7,0)<=MATCH(Gerador!$B$19,Niveis!$A$5:$A$7,0),OR(G6="Todos",G6=Gerador!$B$21)),1,0) -> 0 | I6: =IF(H6=1,COUNTIFS($D$5:D6,D6,$E$5:E6,E6,$H$5:H6,1),0) -> 0 | J6: =COUNTIFS(Exercicios!$C$5:$C$75,D6,Exercicios!$F$5:$F$75,E6,Exercicios!$H$5:$H$75,"Sim") -> 7 | K6: =IF(AND(H6=1,I6<=J6),1,0) -> 0 | L6: =IF(K6=1,COUNTIFS($A$5:A6,A6,$B$5:B6,B6,$K$5:K6,1),0) -> 0 | M6: =IF(K6=1,A6&"-"&B6&"-"&L6,"") | N6: =IF(K6=1,D6&"-"&E6&"-"&I6,"") | O6: =IF(K6=1,INDEX(Exercicios!$B$5:$B$75,MATCH(N6,Exercicios!$I$5:$I$75,0)),"")
A7: 3 | B7: 1 | C7: Corpo todo A | D7: Costas | E7: Composto | F7: Iniciante | G7: Todos | H7: =IF(AND(A7=Gerador!$B$20,MATCH(F7,Niveis!$A$5:$A$7,0)<=MATCH(Gerador!$B$19,Niveis!$A$5:$A$7,0),OR(G7="Todos",G7=Gerador!$B$21)),1,0) -> 0 | I7: =IF(H7=1,COUNTIFS($D$5:D7,D7,$E$5:E7,E7,$H$5:H7,1),0) -> 0 | J7: =COUNTIFS(Exercicios!$C$5:$C$75,D7,Exercicios!$F$5:$F$75,E7,Exercicios!$H$5:$H$75,"Sim") -> 8 | K7: =IF(AND(H7=1,I7<=J7),1,0) -> 0 | L7: =IF(K7=1,COUNTIFS($A$5:A7,A7,$B$5:B7,B7,$K$5:K7,1),0) -> 0 | M7: =IF(K7=1,A7&"-"&B7&"-"&L7,"") | N7: =IF(K7=1,D7&"-"&E7&"-"&I7,"") | O7: =IF(K7=1,INDEX(Exercicios!$B$5:$B$75,MATCH(N7,Exercicios!$I$5:$I$75,0)),"")
A8: 3 | B8: 1 | C8: Corpo todo A | D8: Ombros | E8: Composto | F8: Iniciante | G8: Todos | H8: =IF(AND(A8=Gerador!$B$20,MATCH(F8,Niveis!$A$5:$A$7,0)<=MATCH(Gerador!$B$19,Niveis!$A$5:$A$7,0),OR(G8="Todos",G8=Gerador!$B$21)),1,0) -> 0 | I8: =IF(H8=1,COUNTIFS($D$5:D8,D8,$E$5:E8,E8,$H$5:H8,1),0) -> 0 | J8: =COUNTIFS(Exercicios!$C$5:$C$75,D8,Exercicios!$F$5:$F$75,E8,Exercicios!$H$5:$H$75,"Sim") -> 3 | K8: =IF(AND(H8=1,I8<=J8),1,0) -> 0 | L8: =IF(K8=1,COUNTIFS($A$5:A8,A8,$B$5:B8,B8,$K$5:K8,1),0) -> 0 | M8: =IF(K8=1,A8&"-"&B8&"-"&L8,"") | N8: =IF(K8=1,D8&"-"&E8&"-"&I8,"") | O8: =IF(K8=1,INDEX(Exercicios!$B$5:$B$75,MATCH(N8,Exercicios!$I$5:$I$75,0)),"")
A9: 3 | B9: 1 | C9: Corpo todo A | D9: Peito | E9: Isolado | F9: Intermediário | G9: Todos | H9: =IF(AND(A9=Gerador!$B$20,MATCH(F9,Niveis!$A$5:$A$7,0)<=MATCH(Gerador!$B$19,Niveis!$A$5:$A$7,0),OR(G9="Todos",G9=Gerador!$B$21)),1,0) -> 0 | I9: =IF(H9=1,COUNTIFS($D$5:D9,D9,$E$5:E9,E9,$H$5:H9,1),0) -> 0 | J9: =COUNTIFS(Exercicios!$C$5:$C$75,D9,Exercicios!$F$5:$F$75,E9,Exercicios!$H$5:$H$75,"Sim") -> 3 | K9: =IF(AND(H9=1,I9<=J9),1,0) -> 0 | L9: =IF(K9=1,COUNTIFS($A$5:A9,A9,$B$5:B9,B9,$K$5:K9,1),0) -> 0 | M9: =IF(K9=1,A9&"-"&B9&"-"&L9,"") | N9: =IF(K9=1,D9&"-"&E9&"-"&I9,"") | O9: =IF(K9=1,INDEX(Exercicios!$B$5:$B$75,MATCH(N9,Exercicios!$I$5:$I$75,0)),"")
A10: 3 | B10: 1 | C10: Corpo todo A | D10: Ombros | E10: Isolado | F10: Intermediário | G10: Todos | H10: =IF(AND(A10=Gerador!$B$20,MATCH(F10,Niveis!$A$5:$A$7,0)<=MATCH(Gerador!$B$19,Niveis!$A$5:$A$7,0),OR(G10="Todos",G10=Gerador!$B$21)),1,0) -> 0 | I10: =IF(H10=1,COUNTIFS($D$5:D10,D10,$E$5:E10,E10,$H$5:H10,1),0) -> 0 | J10: =COUNTIFS(Exercicios!$C$5:$C$75,D10,Exercicios!$F$5:$F$75,E10,Exercicios!$H$5:$H$75,"Sim") -> 5 | K10: =IF(AND(H10=1,I10<=J10),1,0) -> 0 | L10: =IF(K10=1,COUNTIFS($A$5:A10,A10,$B$5:B10,B10,$K$5:K10,1),0) -> 0 | M10: =IF(K10=1,A10&"-"&B10&"-"&L10,"") | N10: =IF(K10=1,D10&"-"&E10&"-"&I10,"") | O10: =IF(K10=1,INDEX(Exercicios!$B$5:$B$75,MATCH(N10,Exercicios!$I$5:$I$75,0)),"")
A11: 3 | B11: 1 | C11: Corpo todo A | D11: Peito | E11: Isolado | F11: Iniciante | G11: M | H11: =IF(AND(A11=Gerador!$B$20,MATCH(F11,Niveis!$A$5:$A$7,0)<=MATCH(Gerador!$B$19,Niveis!$A$5:$A$7,0),OR(G11="Todos",G11=Gerador!$B$21)),1,0) -> 0 | I11: =IF(H11=1,COUNTIFS($D$5:D11,D11,$E$5:E11,E11,$H$5:H11,1),0) -> 0 | J11: =COUNTIFS(Exercicios!$C$5:$C$75,D11,Exercicios!$F$5:$F$75,E11,Exercicios!$H$5:$H$75,"Sim") -> 3 | K11: =IF(AND(H11=1,I11<=J11),1,0) -> 0 | L11: =IF(K11=1,COUNTIFS($A$5:A11,A11,$B$5:B11,B11,$K$5:K11,1),0) -> 0 | M11: =IF(K11=1,A11&"-"&B11&"-"&L11,"") | N11: =IF(K11=1,D11&"-"&E11&"-"&I11,"") | O11: =IF(K11=1,INDEX(Exercicios!$B$5:$B$75,MATCH(N11,Exercicios!$I$5:$I$75,0)),"")
A12: 3 | B12: 1 | C12: Corpo todo A | D12: Ombros | E12: Isolado | F12: Iniciante | G12: F | H12: =IF(AND(A12=Gerador!$B$20,MATCH(F12,Niveis!$A$5:$A$7,0)<=MATCH(Gerador!$B$19,Niveis!$A$5:$A$7,0),OR(G12="Todos",G12=Gerador!$B$21)),1,0) -> 0 | I12: =IF(H12=1,COUNTIFS($D$5:D12,D12,$E$5:E12,E12,$H$5:H12,1),0) -> 0 | J12: =COUNTIFS(Exercicios!$C$5:$C$75,D12,Exercicios!$F$5:$F$75,E12,Exercicios!$H$5:$H$75,"Sim") -> 5 | K12: =IF(AND(H12=1,I12<=J12),1,0) -> 0 | L12: =IF(K12=1,COUNTIFS($A$5:A12,A12,$B$5:B12,B12,$K$5:K12,1),0) -> 0 | M12: =IF(K12=1,A12&"-"&B12&"-"&L12,"") | N12: =IF(K12=1,D12&"-"&E12&"-"&I12,"") | O12: =IF(K12=1,INDEX(Exercicios!$B$5:$B$75,MATCH(N12,Exercicios!$I$5:$I$75,0)),"")
A13: 3 | B13: 1 | C13: Corpo todo A | D13: Bíceps | E13: Isolado | F13: Iniciante | G13: N | H13: =IF(AND(A13=Gerador!$B$20,MATCH(F13,Niveis!$A$5:$A$7,0)<=MATCH(Gerador!$B$19,Niveis!$A$5:$A$7,0),OR(G13="Todos",G13=Gerador!$B$21)),1,0) -> 0 | I13: =IF(H13=1,COUNTIFS($D$5:D13,D13,$E$5:E13,E13,$H$5:H13,1),0) -> 0 | J13: =COUNTIFS(Exercicios!$C$5:$C$75,D13,Exercicios!$F$5:$F$75,E13,Exercicios!$H$5:$H$75,"Sim") -> 5 | K13: =IF(AND(H13=1,I13<=J13),1,0) -> 0 | L13: =IF(K13=1,COUNTIFS($A$5:A13,A13,$B$5:B13,B13,$K$5:K13,1),0) -> 0 | M13: =IF(K13=1,A13&"-"&B13&"-"&L13,"") | N13: =IF(K13=1,D13&"-"&E13&"-"&I13,"") | O13: =IF(K13=1,INDEX(Exercicios!$B$5:$B$75,MATCH(N13,Exercicios!$I$5:$I$75,0)),"")
A14: 3 | B14: 1 | C14: Corpo todo A | D14: Abdômen | E14: Isolado | F14: Iniciante | G14: Todos | H14: =IF(AND(A14=Gerador!$B$20,MATCH(F14,Niveis!$A$5:$A$7,0)<=MATCH(Gerador!$B$19,Niveis!$A$5:$A$7,0),OR(G14="Todos",G14=Gerador!$B$21)),1,0) -> 0 | I14: =IF(H14=1,COUNTIFS($D$5:D14,D14,$E$5:E14,E14,$H$5:H14,1),0) -> 0 | J14: =COUNTIFS(Exercicios!$C$5:$C$75,D14,Exercicios!$F$5:$F$75,E14,Exercicios!$H$5:$H$75,"Sim") -> 6 | K14: =IF(AND(H14=1,I14<=J14),1,0) -> 0 | L14: =IF(K14=1,COUNTIFS($A$5:A14,A14,$B$5:B14,B14,$K$5:K14,1),0) -> 0 | M14: =IF(K14=1,A14&"-"&B14&"-"&L14,"") | N14: =IF(K14=1,D14&"-"&E14&"-"&I14,"") | O14: =IF(K14=1,INDEX(Exercicios!$B$5:$B$75,MATCH(N14,Exercicios!$I$5:$I$75,0)),"")
A15: 3 | B15: 2 | C15: Corpo todo B | D15: Posterior de coxa | E15: Composto | F15: Iniciante | G15: Todos | H15: =IF(AND(A15=Gerador!$B$20,MATCH(F15,Niveis!$A$5:$A$7,0)<=MATCH(Gerador!$B$19,Niveis!$A$5:$A$7,0),OR(G15="Todos",G15=Gerador!$B$21)),1,0) -> 0 | I15: =IF(H15=1,COUNTIFS($D$5:D15,D15,$E$5:E15,E15,$H$5:H15,1),0) -> 0 | J15: =COUNTIFS(Exercicios!$C$5:$C$75,D15,Exercicios!$F$5:$F$75,E15,Exercicios!$H$5:$H$75,"Sim") -> 4 | K15: =IF(AND(H15=1,I15<=J15),1,0) -> 0 | L15: =IF(K15=1,COUNTIFS($A$5:A15,A15,$B$5:B15,B15,$K$5:K15,1),0) -> 0 | M15: =IF(K15=1,A15&"-"&B15&"-"&L15,"") | N15: =IF(K15=1,D15&"-"&E15&"-"&I15,"") | O15: =IF(K15=1,INDEX(Exercicios!$B$5:$B$75,MATCH(N15,Exercicios!$I$5:$I$75,0)),"")
A16: 3 | B16: 2 | C16: Corpo todo B | D16: Glúteos | E16: Composto | F16: Iniciante | G16: Todos | H16: =IF(AND(A16=Gerador!$B$20,MATCH(F16,Niveis!$A$5:$A$7,0)<=MATCH(Gerador!$B$19,Niveis!$A$5:$A$7,0),OR(G16="Todos",G16=Gerador!$B$21)),1,0) -> 0 | I16: =IF(H16=1,COUNTIFS($D$5:D16,D16,$E$5:E16,E16,$H$5:H16,1),0) -> 0 | J16: =COUNTIFS(Exercicios!$C$5:$C$75,D16,Exercicios!$F$5:$F$75,E16,Exercicios!$H$5:$H$75,"Sim") -> 3 | K16: =IF(AND(H16=1,I16<=J16),1,0) -> 0 | L16: =IF(K16=1,COUNTIFS($A$5:A16,A16,$B$5:B16,B16,$K$5:K16,1),0) -> 0 | M16: =IF(K16=1,A16&"-"&B16&"-"&L16,"") | N16: =IF(K16=1,D16&"-"&E16&"-"&I16,"") | O16: =IF(K16=1,INDEX(Exercicios!$B$5:$B$75,MATCH(N16,Exercicios!$I$5:$I$75,0)),"")
... A105: 5 | B105: 5 | C105: Inferior + Core | D105: Abdômen | E105: Isolado | F105: Avançado | G105: N | H105: =IF(AND(A105=Gerador!$B$20,MATCH(F105,Niveis!$A$5:$A$7,0)<=MATCH(Gerador!$B$19,Niveis!$A$5:$A$7,0),OR(G105="Todos",G105=Gerador!$B$21)),1,0) -> 0 | I105: =IF(H105=1,COUNTIFS($D$5:D105,D105,$E$5:E105,E105,$H$5:H105,1),0) -> 0 | J105: =COUNTIFS(Exercicios!$C$5:$C$75,D105,Exercicios!$F$5:$F$75,E105,Exercicios!$H$5:$H$75,"Sim") -> 6 | K105: =IF(AND(H105=1,I105<=J105),1,0) -> 0 | L105: =IF(K105=1,COUNTIFS($A$5:A105,A105,$B$5:B105,B105,$K$5:K105,1),0) -> 0 | M105: =IF(K105=1,A105&"-"&B105&"-"&L105,"") | N105: =IF(K105=1,D105&"-"&E105&"-"&I105,"") | O105: =IF(K105=1,INDEX(Exercicios!$B$5:$B$75,MATCH(N105,Exercicios!$I$5:$I$75,0)),"")

Sheet Exercicios
A1: Lista padrão de exercícios (corpo inteiro)
A2: A ORDEM das linhas dentro de cada Grupo+Tipo é a ordem de escolha do algoritmo (melhor opção disponível para o nível vem primeiro). Mude a ordem para mudar o treino padrão.
A4: # | B4: Exercício | C4: Grupo principal | D4: Grupos secundários | E4: Equipamento | F4: Tipo | G4: Nível mínimo | H4: Disponível p/ nível efetivo | I4: Chave (aux.) | K4: Cobertura | L4: Total | M4: Disponíveis p/ nível efetivo
A5: 1 | B5: Supino reto com barra | C5: Peito | D5: Tríceps, Ombros | E5: Barra | F5: Composto | G5: Intermediário | H5: =IF(MATCH(G5,Niveis!$A$5:$A$7,0)<=MATCH(Gerador!$B$19,Niveis!$A$5:$A$7,0),"Sim","Não") -> Sim | I5: =IF(H5="Sim",C5&"-"&F5&"-"&COUNTIFS($C$5:C5,C5,$F$5:F5,F5,$H$5:H5,"Sim"),"") -> Peito-Composto-1 | K5: Peito | L5: =COUNTIF($C$5:$C$75,K5) -> 10 | M5: =COUNTIFS($C$5:$C$75,K5,$H$5:$H$75,"Sim") -> 10
A6: 2 | B6: Supino inclinado com barra | C6: Peito | D6: Ombros, Tríceps | E6: Barra | F6: Composto | G6: Intermediário | H6: =IF(MATCH(G6,Niveis!$A$5:$A$7,0)<=MATCH(Gerador!$B$19,Niveis!$A$5:$A$7,0),"Sim","Não") -> Sim | I6: =IF(H6="Sim",C6&"-"&F6&"-"&COUNTIFS($C$5:C6,C6,$F$5:F6,F6,$H$5:H6,"Sim"),"") -> Peito-Composto-2 | K6: Costas | L6: =COUNTIF($C$5:$C$75,K6) -> 9 | M6: =COUNTIFS($C$5:$C$75,K6,$H$5:$H$75,"Sim") -> 9
A7: 3 | B7: Supino reto com halteres | C7: Peito | D7: Tríceps, Ombros | E7: Halteres | F7: Composto | G7: Iniciante | H7: =IF(MATCH(G7,Niveis!$A$5:$A$7,0)<=MATCH(Gerador!$B$19,Niveis!$A$5:$A$7,0),"Sim","Não") -> Sim | I7: =IF(H7="Sim",C7&"-"&F7&"-"&COUNTIFS($C$5:C7,C7,$F$5:F7,F7,$H$5:H7,"Sim"),"") -> Peito-Composto-3 | K7: Ombros | L7: =COUNTIF($C$5:$C$75,K7) -> 8 | M7: =COUNTIFS($C$5:$C$75,K7,$H$5:$H$75,"Sim") -> 8
A8: 4 | B8: Supino inclinado com halteres | C8: Peito | D8: Ombros, Tríceps | E8: Halteres | F8: Composto | G8: Iniciante | H8: =IF(MATCH(G8,Niveis!$A$5:$A$7,0)<=MATCH(Gerador!$B$19,Niveis!$A$5:$A$7,0),"Sim","Não") -> Sim | I8: =IF(H8="Sim",C8&"-"&F8&"-"&COUNTIFS($C$5:C8,C8,$F$5:F8,F8,$H$5:H8,"Sim"),"") -> Peito-Composto-4 | K8: Bíceps | L8: =COUNTIF($C$5:$C$75,K8) -> 5 | M8: =COUNTIFS($C$5:$C$75,K8,$H$5:$H$75,"Sim") -> 5
A9: 5 | B9: Chest press (máquina) | C9: Peito | D9: Tríceps, Ombros | E9: Máquina | F9: Composto | G9: Iniciante | H9: =IF(MATCH(G9,Niveis!$A$5:$A$7,0)<=MATCH(Gerador!$B$19,Niveis!$A$5:$A$7,0),"Sim","Não") -> Sim | I9: =IF(H9="Sim",C9&"-"&F9&"-"&COUNTIFS($C$5:C9,C9,$F$5:F9,F9,$H$5:H9,"Sim"),"") -> Peito-Composto-5 | K9: Tríceps | L9: =COUNTIF($C$5:$C$75,K9) -> 5 | M9: =COUNTIFS($C$5:$C$75,K9,$H$5:$H$75,"Sim") -> 5
A10: 6 | B10: Flexão de braços | C10: Peito | D10: Tríceps, Ombros, Abdômen | E10: Peso do corpo | F10: Composto | G10: Iniciante | H10: =IF(MATCH(G10,Niveis!$A$5:$A$7,0)<=MATCH(Gerador!$B$19,Niveis!$A$5:$A$7,0),"Sim","Não") -> Sim | I10: =IF(H10="Sim",C10&"-"&F10&"-"&COUNTIFS($C$5:C10,C10,$F$5:F10,F10,$H$5:H10,"Sim"),"") -> Peito-Composto-6 | K10: Quadríceps | L10: =COUNTIF($C$5:$C$75,K10) -> 9 | M10: =COUNTIFS($C$5:$C$75,K10,$H$5:$H$75,"Sim") -> 9
A11: 7 | B11: Mergulho nas paralelas (foco peito) | C11: Peito | D11: Tríceps, Ombros | E11: Peso do corpo | F11: Composto | G11: Intermediário | H11: =IF(MATCH(G11,Niveis!$A$5:$A$7,0)<=MATCH(Gerador!$B$19,Niveis!$A$5:$A$7,0),"Sim","Não") -> Sim | I11: =IF(H11="Sim",C11&"-"&F11&"-"&COUNTIFS($C$5:C11,C11,$F$5:F11,F11,$H$5:H11,"Sim"),"") -> Peito-Composto-7 | K11: Posterior de coxa | L11: =COUNTIF($C$5:$C$75,K11) -> 6 | M11: =COUNTIFS($C$5:$C$75,K11,$H$5:$H$75,"Sim") -> 6
A12: 8 | B12: Crossover na polia | C12: Peito | D12: Ombros | E12: Polia | F12: Isolado | G12: Intermediário | H12: =IF(MATCH(G12,Niveis!$A$5:$A$7,0)<=MATCH(Gerador!$B$19,Niveis!$A$5:$A$7,0),"Sim","Não") -> Sim | I12: =IF(H12="Sim",C12&"-"&F12&"-"&COUNTIFS($C$5:C12,C12,$F$5:F12,F12,$H$5:H12,"Sim"),"") -> Peito-Isolado-1 | K12: Glúteos | L12: =COUNTIF($C$5:$C$75,K12) -> 6 | M12: =COUNTIFS($C$5:$C$75,K12,$H$5:$H$75,"Sim") -> 6
A13: 9 | B13: Crucifixo com halteres | C13: Peito | D13: Ombros | E13: Halteres | F13: Isolado | G13: Intermediário | H13: =IF(MATCH(G13,Niveis!$A$5:$A$7,0)<=MATCH(Gerador!$B$19,Niveis!$A$5:$A$7,0),"Sim","Não") -> Sim | I13: =IF(H13="Sim",C13&"-"&F13&"-"&COUNTIFS($C$5:C13,C13,$F$5:F13,F13,$H$5:H13,"Sim"),"") -> Peito-Isolado-2 | K13: Panturrilha | L13: =COUNTIF($C$5:$C$75,K13) -> 3 | M13: =COUNTIFS($C$5:$C$75,K13,$H$5:$H$75,"Sim") -> 3
A14: 10 | B14: Crucifixo na máquina (peck deck) | C14: Peito | D14: — | E14: Máquina | F14: Isolado | G14: Iniciante | H14: =IF(MATCH(G14,Niveis!$A$5:$A$7,0)<=MATCH(Gerador!$B$19,Niveis!$A$5:$A$7,0),"Sim","Não") -> Sim | I14: =IF(H14="Sim",C14&"-"&F14&"-"&COUNTIFS($C$5:C14,C14,$F$5:F14,F14,$H$5:H14,"Sim"),"") -> Peito-Isolado-3 | K14: Abdômen | L14: =COUNTIF($C$5:$C$75,K14) -> 6 | M14: =COUNTIFS($C$5:$C$75,K14,$H$5:$H$75,"Sim") -> 6
A15: 11 | B15: Remada curvada com barra | C15: Costas | D15: Bíceps, Lombar | E15: Barra | F15: Composto | G15: Intermediário | H15: =IF(MATCH(G15,Niveis!$A$5:$A$7,0)<=MATCH(Gerador!$B$19,Niveis!$A$5:$A$7,0),"Sim","Não") -> Sim | I15: =IF(H15="Sim",C15&"-"&F15&"-"&COUNTIFS($C$5:C15,C15,$F$5:F15,F15,$H$5:H15,"Sim"),"") -> Costas-Composto-1 | K15: Lombar | L15: =COUNTIF($C$5:$C$75,K15) -> 2 | M15: =COUNTIFS($C$5:$C$75,K15,$H$5:$H$75,"Sim") -> 2
A16: 12 | B16: Barra fixa (pull-up) | C16: Costas | D16: Bíceps | E16: Peso do corpo | F16: Composto | G16: Intermediário | H16: =IF(MATCH(G16,Niveis!$A$5:$A$7,0)<=MATCH(Gerador!$B$19,Niveis!$A$5:$A$7,0),"Sim","Não") -> Sim | I16: =IF(H16="Sim",C16&"-"&F16&"-"&COUNTIFS($C$5:C16,C16,$F$5:F16,F16,$H$5:H16,"Sim"),"") -> Costas-Composto-2 | K16: Antebraço | L16: =COUNTIF($C$5:$C$75,K16) -> 2 | M16: =COUNTIFS($C$5:$C$75,K16,$H$5:$H$75,"Sim") -> 2
A17: 13 | B17: Puxada frontal na polia | C17: Costas | D17: Bíceps | E17: Polia | F17: Composto | G17: Iniciante | H17: =IF(MATCH(G17,Niveis!$A$5:$A$7,0)<=MATCH(Gerador!$B$19,Niveis!$A$5:$A$7,0),"Sim","Não") -> Sim | I17: =IF(H17="Sim",C17&"-"&F17&"-"&COUNTIFS($C$5:C17,C17,$F$5:F17,F17,$H$5:H17,"Sim"),"") -> Costas-Composto-3 | K17: Total | L17: =SUM(L5:L16) -> 71 | M17: =SUM(M5:M16) -> 71
A18: 14 | B18: Remada baixa na polia (triângulo) | C18: Costas | D18: Bíceps | E18: Polia | F18: Composto | G18: Iniciante | H18: =IF(MATCH(G18,Niveis!$A$5:$A$7,0)<=MATCH(Gerador!$B$19,Niveis!$A$5:$A$7,0),"Sim","Não") -> Sim | I18: =IF(H18="Sim",C18&"-"&F18&"-"&COUNTIFS($C$5:C18,C18,$F$5:F18,F18,$H$5:H18,"Sim"),"") -> Costas-Composto-4
A19: 15 | B19: Remada unilateral com haltere (serrote) | C19: Costas | D19: Bíceps | E19: Halteres | F19: Composto | G19: Iniciante | H19: =IF(MATCH(G19,Niveis!$A$5:$A$7,0)<=MATCH(Gerador!$B$19,Niveis!$A$5:$A$7,0),"Sim","Não") -> Sim | I19: =IF(H19="Sim",C19&"-"&F19&"-"&COUNTIFS($C$5:C19,C19,$F$5:F19,F19,$H$5:H19,"Sim"),"") -> Costas-Composto-5
A20: 16 | B20: Remada na máquina | C20: Costas | D20: Bíceps | E20: Máquina | F20: Composto | G20: Iniciante | H20: =IF(MATCH(G20,Niveis!$A$5:$A$7,0)<=MATCH(Gerador!$B$19,Niveis!$A$5:$A$7,0),"Sim","Não") -> Sim | I20: =IF(H20="Sim",C20&"-"&F20&"-"&COUNTIFS($C$5:C20,C20,$F$5:F20,F20,$H$5:H20,"Sim"),"") -> Costas-Composto-6
A21: 17 | B21: Barra fixa assistida | C21: Costas | D21: Bíceps | E21: Máquina assistida | F21: Composto | G21: Iniciante | H21: =IF(MATCH(G21,Niveis!$A$5:$A$7,0)<=MATCH(Gerador!$B$19,Niveis!$A$5:$A$7,0),"Sim","Não") -> Sim | I21: =IF(H21="Sim",C21&"-"&F21&"-"&COUNTIFS($C$5:C21,C21,$F$5:F21,F21,$H$5:H21,"Sim"),"") -> Costas-Composto-7
A22: 18 | B22: Barra fixa com carga | C22: Costas | D22: Bíceps | E22: Peso do corpo + anilha | F22: Composto | G22: Avançado | H22: =IF(MATCH(G22,Niveis!$A$5:$A$7,0)<=MATCH(Gerador!$B$19,Niveis!$A$5:$A$7,0),"Sim","Não") -> Sim | I22: =IF(H22="Sim",C22&"-"&F22&"-"&COUNTIFS($C$5:C22,C22,$F$5:F22,F22,$H$5:H22,"Sim"),"") -> Costas-Composto-8
A23: 19 | B23: Pullover na polia (braços estendidos) | C23: Costas | D23: Peito | E23: Polia | F23: Isolado | G23: Intermediário | H23: =IF(MATCH(G23,Niveis!$A$5:$A$7,0)<=MATCH(Gerador!$B$19,Niveis!$A$5:$A$7,0),"Sim","Não") -> Sim | I23: =IF(H23="Sim",C23&"-"&F23&"-"&COUNTIFS($C$5:C23,C23,$F$5:F23,F23,$H$5:H23,"Sim"),"") -> Costas-Isolado-1
A24: 20 | B24: Desenvolvimento militar com barra | C24: Ombros | D24: Tríceps | E24: Barra | F24: Composto | G24: Intermediário | H24: =IF(MATCH(G24,Niveis!$A$5:$A$7,0)<=MATCH(Gerador!$B$19,Niveis!$A$5:$A$7,0),"Sim","Não") -> Sim | I24: =IF(H24="Sim",C24&"-"&F24&"-"&COUNTIFS($C$5:C24,C24,$F$5:F24,F24,$H$5:H24,"Sim"),"") -> Ombros-Composto-1
A25: 21 | B25: Desenvolvimento com halteres | C25: Ombros | D25: Tríceps | E25: Halteres | F25: Composto | G25: Iniciante | H25: =IF(MATCH(G25,Niveis!$A$5:$A$7,0)<=MATCH(Gerador!$B$19,Niveis!$A$5:$A$7,0),"Sim","Não") -> Sim | I25: =IF(H25="Sim",C25&"-"&F25&"-"&COUNTIFS($C$5:C25,C25,$F$5:F25,F25,$H$5:H25,"Sim"),"") -> Ombros-Composto-2
A26: 22 | B26: Desenvolvimento na máquina | C26: Ombros | D26: Tríceps | E26: Máquina | F26: Composto | G26: Iniciante | H26: =IF(MATCH(G26,Niveis!$A$5:$A$7,0)<=MATCH(Gerador!$B$19,Niveis!$A$5:$A$7,0),"Sim","Não") -> Sim | I26: =IF(H26="Sim",C26&"-"&F26&"-"&COUNTIFS($C$5:C26,C26,$F$5:F26,F26,$H$5:H26,"Sim"),"") -> Ombros-Composto-3
A27: 23 | B27: Elevação lateral com halteres | C27: Ombros | D27: — | E27: Halteres | F27: Isolado | G27: Iniciante | H27: =IF(MATCH(G27,Niveis!$A$5:$A$7,0)<=MATCH(Gerador!$B$19,Niveis!$A$5:$A$7,0),"Sim","Não") -> Sim | I27: =IF(H27="Sim",C27&"-"&F27&"-"&COUNTIFS($C$5:C27,C27,$F$5:F27,F27,$H$5:H27,"Sim"),"") -> Ombros-Isolado-1
A28: 24 | B28: Crucifixo inverso na máquina (deltoide posterior) | C28: Ombros | D28: Costas | E28: Máquina | F28: Isolado | G28: Iniciante | H28: =IF(MATCH(G28,Niveis!$A$5:$A$7,0)<=MATCH(Gerador!$B$19,Niveis!$A$5:$A$7,0),"Sim","Não") -> Sim | I28: =IF(H28="Sim",C28&"-"&F28&"-"&COUNTIFS($C$5:C28,C28,$F$5:F28,F28,$H$5:H28,"Sim"),"") -> Ombros-Isolado-2
A29: 25 | B29: Elevação lateral na polia | C29: Ombros | D29: — | E29: Polia | F29: Isolado | G29: Intermediário | H29: =IF(MATCH(G29,Niveis!$A$5:$A$7,0)<=MATCH(Gerador!$B$19,Niveis!$A$5:$A$7,0),"Sim","Não") -> Sim | I29: =IF(H29="Sim",C29&"-"&F29&"-"&COUNTIFS($C$5:C29,C29,$F$5:F29,F29,$H$5:H29,"Sim"),"") -> Ombros-Isolado-3
... A75: 71 | B75: Rosca inversa | C75: Antebraço | D75: Bíceps | E75: Barra | F75: Isolado | G75: Iniciante | H75: =IF(MATCH(G75,Niveis!$A$5:$A$7,0)<=MATCH(Gerador!$B$19,Niveis!$A$5:$A$7,0),"Sim","Não") -> Sim | I75: =IF(H75="Sim",C75&"-"&F75&"-"&COUNTIFS($C$5:C75,C75,$F$5:F75,F75,$H$5:H75,"Sim"),"") -> Antebraço-Isolado-2
